<?xml version="1.0" ?>
<!-- =================================================================================== -->
<!-- |    This document was autogenerated by xacro from /home/phufaru/cs_ws/src/irwb_robot_pkg/urdf/irwb.xacro | -->
<!-- |    EDITING THIS FILE BY HAND IS NOT RECOMMENDED                                 | -->
<!-- =================================================================================== -->
<robot name="irwb_full">
    <gazebo reference="body_link">
        <mu1>0.2</mu1>
        <mu2>0.2</mu2>
        <material>Gazebo/Red</material>
        <plugin name="gazebo_ros_control" filename="libgazebo_ros_control.so">
            <robotNamespace>/</robotNamespace>
        </plugin>
    </gazebo>
    <gazebo reference="wheel1_link">
        <mu1>0.2</mu1>
        <mu2>0.2</mu2>
        <material>Gazebo/Yellow</material>
    </gazebo>
    <gazebo reference="wheel2_link">
        <mu1>0.2</mu1>
        <mu2>0.2</mu2>
        <material>Gazebo/Yellow</material>
    </gazebo>
    <gazebo reference="wheel3_link">
        <mu1>0.2</mu1>
        <mu2>0.2</mu2>
        <material>Gazebo/Yellow</material>
    </gazebo>
    <gazebo reference="wheel4_link">
        <mu1>0.2</mu1>
        <mu2>0.2</mu2>
        <material>Gazebo/Yellow</material>
    </gazebo>
    <!-- Arm Links -->
    <!-- <gazebo reference="base_link">
    <mu1>0.9</mu1>  
    <mu2>0.9</mu2>
    <material>Gazebo/Blue</material>
  </gazebo>

  <gazebo reference="arm1_p_link">
    <mu1>0.9</mu1>
    <mu2>0.9</mu2>
    <material>Gazebo/Yellow</material>
  </gazebo>

  <gazebo reference="arm2_link">
    <mu1>0.9</mu1>
    <mu2>0.9</mu2>
    <material>Gazebo/Red</material>
  </gazebo>

  <gazebo reference="arm3_link">
    <mu1>0.9</mu1>
    <mu2>0.9</mu2>
    <material>Gazebo/Red</material>
  </gazebo>

  <gazebo reference="arm4_link">
    <mu1>0.9</mu1>
    <mu2>0.9</mu2>
    <material>Gazebo/Green</material>
  </gazebo> -->
    <!-- Base Controller -->
    <gazebo>
        <plugin filename="libgazebo_ros_skid_steer_drive.so" name="skid_steer_drive_controller">
            <updateRate>100.0</updateRate>
            <robotNamespace />
            <leftFrontJoint>wheel4_joint</leftFrontJoint>
            <rightFrontJoint>wheel3_joint</rightFrontJoint>
            <leftRearJoint>wheel2_joint</leftRearJoint>
            <rightRearJoint>wheel1_joint</rightRearJoint>
            <wheelSeparation>1.15</wheelSeparation>
            <wheelDiameter>0.2</wheelDiameter>
            <torque>1000</torque>
            <commandTopic>cmd_vel</commandTopic>
            <odometryTopic>odom</odometryTopic>
            <odometryFrame>odom</odometryFrame>
            <robotBaseFrame>dummy</robotBaseFrame>
            <publishWheelTF>true</publishWheelTF>
            <publishOdom>true</publishOdom>
            <publishWheelJointState>true</publishWheelJointState>
            <covariance_x>0.0001</covariance_x>
            <covariance_y>0.0001</covariance_y>
            <covariance_yaw>0.01</covariance_yaw>
        </plugin>
    </gazebo>
    <!--####################################-->
    <!--# Define all Links and Joints here #-->
    <!--####################################-->
    <!-- Mandatory "dummy" link and joint -->
    <link name="dummy" />
    <joint name="dummy_joint" type="fixed">
        <parent link="dummy" />
        <child link="body_link" />
    </joint>
    <!--####################################-->
    <!--# body_link with hole in the front #-->
    <!--####################################-->
    <link name="body_link">
        <visual>
            <origin rpy="0 0 0" xyz="-0.5 0 0" />
            <geometry>
                <box size="1.0 1 0.7" />
                <!-- Solid back part -->
            </geometry>
        </visual>
        <visual>
            <origin rpy="0 0 0" xyz="0.04999999999999999 0 0" />
            <!-- Shaded area 1 -->
            <geometry>
                <box size="0.1 0.8 0.7" />
            </geometry>
        </visual>
        <visual>
            <origin rpy="0 0 0" xyz="0.95 0 0" />
            <!-- Shaded area 2 -->
            <geometry>
                <box size="0.1 0.8 0.7" />
            </geometry>
        </visual>
        <visual>
            <origin rpy="0 0 0" xyz="0.5 0.45 0" />
            <!-- Unshaded area 1 -->
            <geometry>
                <box size="1.0 0.1 0.7" />
            </geometry>
        </visual>
        <visual>
            <origin rpy="0 0 0" xyz="0.5 -0.45 0" />
            <!-- Unshaded area 2 -->
            <geometry>
                <box size="1.0 0.1 0.7" />
            </geometry>
        </visual>
        <visual>
            <origin rpy="0 0 0" xyz="0.5 0 -0.3" />
            <!-- Base of hole -->
            <geometry>
                <box size="0.8 0.8 0.1" />
            </geometry>
        </visual>
        <collision>
            <origin rpy="0 0 0" xyz="-0.5 0 0" />
            <geometry>
                <box size="1.0 1 0.7" />
            </geometry>
        </collision>
        <collision>
            <origin rpy="0 0 0" xyz="0.04999999999999999 0 0" />
            <geometry>
                <box size="0.1 0.8 0.7" />
            </geometry>
        </collision>
        <collision>
            <origin rpy="0 0 0" xyz="0.95 0 0" />
            <geometry>
                <box size="0.1 0.8 0.7" />
            </geometry>
        </collision>
        <collision>
            <origin rpy="0 0 0" xyz="0.5 0.45 0" />
            <geometry>
                <box size="1.0 0.1 0.7" />
            </geometry>
        </collision>
        <collision>
            <origin rpy="0 0 0" xyz="0.5 -0.45 0" />
            <geometry>
                <box size="1.0 0.1 0.7" />
            </geometry>
        </collision>
        <collision>
            <origin rpy="0 0 0" xyz="0.5 0 -0.3" />
            <geometry>
                <box size="0.8 0.8 0.1" />
            </geometry>
        </collision>
        <inertial>
            <origin rpy="0 0 0" xyz="0 0 0" />
            <mass value="3793.9999999999995" />
            <inertia ixx="471.08833333333325" ixy="0" ixz="0" iyy="1419.5883333333331" iyz="0" izz="1580.833333333333" />
        </inertial>
    </link>
    <!--####################################-->
    <!--#         end of body_link         #-->
    <!--####################################-->
    <!--# Joint from iRWB to wheel 1 #-->
    <joint name="wheel1_joint" type="continuous">
        <parent link="body_link" />
        <child link="wheel1_link" />
        <origin rpy="0 0 0" xyz="    -0.76     -0.575     -0.3" />
        <axis xyz="0 1 0" />
        <limit effort="1000" velocity="1000" />
        <dynamics damping="1.0" friction="1.0" />
    </joint>
    <!--### back right wheel1 ###-->
    <link name="wheel1_link">
        <visual>
            <origin rpy="1.5708 0 0" xyz="0 0 0" />
            <geometry>
                <cylinder length="0.15" radius="0.2" />
            </geometry>
        </visual>
        <collision>
            <origin rpy="1.5708 0 0" xyz="0 0 0" />
            <geometry>
                <cylinder length="0.15" radius="0.2" />
            </geometry>
        </collision>
        <inertial>
            <origin rpy="0 0 0" xyz="0 0 0" />
            <mass value="28.274333873301" />
            <inertia ixx="0.11674777957766999" ixy="0.0" ixz="0.0" iyy="0.11674777957766999" iyz="0.0" izz="0.56548667746602" />
        </inertial>
    </link>
    <!--# Joint from iRWB to wheel 2 #-->
    <joint name="wheel2_joint" type="continuous">
        <parent link="body_link" />
        <child link="wheel2_link" />
        <origin rpy="0 0 0" xyz="      -0.76       0.575       -0.3" />
        <axis xyz="0 1 0" />
        <limit effort="1000" velocity="1000" />
        <dynamics damping="1.0" friction="1.0" />
    </joint>
    <!--### back left wheel2 ###-->
    <link name="wheel2_link">
        <visual>
            <origin rpy="1.5708 0 0" xyz="0 0 0" />
            <geometry>
                <cylinder length="0.15" radius="0.2" />
            </geometry>
        </visual>
        <collision>
            <origin rpy="1.5708 0 0" xyz="0 0 0" />
            <geometry>
                <cylinder length="0.15" radius="0.2" />
            </geometry>
        </collision>
        <inertial>
            <origin rpy="0 0 0" xyz="0 0 0" />
            <mass value="28.274333873301" />
            <inertia ixx="0.11674777957766999" ixy="0.0" ixz="0.0" iyy="0.11674777957766999" iyz="0.0" izz="0.56548667746602" />
        </inertial>
    </link>
    <!--# Joint from iRWB to wheel 3 #-->
    <joint name="wheel3_joint" type="continuous">
        <parent link="body_link" />
        <child link="wheel3_link" />
        <origin rpy="0 0 0" xyz="      0.76       -0.575       -0.3" />
        <axis xyz="0 1 0" />
        <limit effort="1000" velocity="1000" />
        <dynamics damping="1.0" friction="1.0" />
    </joint>
    <!--### front right wheel3 ###-->
    <link name="wheel3_link">
        <visual>
            <origin rpy="1.5708 0 0" xyz="0 0 0" />
            <geometry>
                <cylinder length="0.15" radius="0.2" />
            </geometry>
        </visual>
        <collision>
            <origin rpy="1.5708 0 0" xyz="0 0 0" />
            <geometry>
                <cylinder length="0.15" radius="0.2" />
            </geometry>
        </collision>
        <inertial>
            <origin rpy="0 0 0" xyz="0 0 0" />
            <mass value="28.274333873301" />
            <inertia ixx="0.11674777957766999" ixy="0.0" ixz="0.0" iyy="0.11674777957766999" iyz="0.0" izz="0.56548667746602" />
        </inertial>
    </link>
    <!--# Joint from iRWB to wheel 4 #-->
    <joint name="wheel4_joint" type="continuous">
        <parent link="body_link" />
        <child link="wheel4_link" />
        <origin rpy="0 0 0" xyz="      0.76       0.575       -0.3" />
        <axis xyz="0 1 0" />
        <limit effort="1000" velocity="1000" />
        <dynamics damping="1.0" friction="1.0" />
    </joint>
    <!--### front left wheel4 ###-->
    <link name="wheel4_link">
        <visual>
            <origin rpy="1.5708 0 0" xyz="0 0 0" />
            <geometry>
                <cylinder length="0.15" radius="0.2" />
            </geometry>
        </visual>
        <collision>
            <origin rpy="1.5708 0 0" xyz="0 0 0" />
            <geometry>
                <cylinder length="0.15" radius="0.2" />
            </geometry>
        </collision>
        <inertial>
            <origin rpy="0 0 0" xyz="0 0 0" />
            <mass value="28.274333873301" />
            <inertia ixx="0.11674777957766999" ixy="0.0" ixz="0.0" iyy="0.11674777957766999" iyz="0.0" izz="0.56548667746602" />
        </inertial>
    </link>
    <!-- Materials -->
    <material name="aluminum">
        <color rgba="0.7 0.7 0.7 1" />
    </material>
    <material name="gripper_color">
        <color rgba="0.9 0.9 0.9 1" />
    </material>
    <link name="base_link">
        <visual>
            <origin rpy="0 0 0" xyz="0 0 0" />
            <geometry>
                <box size="0.2 1 0.1" />
            </geometry>
            <material name="aluminum" />
        </visual>
        <collision>
            <origin rpy="0 0 0" xyz="0 0 0" />
            <geometry>
                <box size="0.2 1 0.1" />
            </geometry>
        </collision>
        <inertial>
            <origin rpy="0 0 0" xxyz="0 0 0" xyz="0 0 0" />
            <mass value="54.2" />
            <inertia ixx="4.561833333333333" ixy="0" ixz="0" iyy="0.22583333333333339" iyz="0" izz="4.697333333333334" />
        </inertial>
    </link>
    <link name="arm1_p_link">
        <visual>
            <origin rpy="0 0 0" xyz="0 0 0" />
            <geometry>
                <cylinder length="0.1" radius="0.1" />
            </geometry>
            <material name="aluminum" />
        </visual>
        <collision>
            <origin rpy="0 0 0" xyz="0 0 0" />
            <geometry>
                <cylinder length="0.1" radius="0.1" />
            </geometry>
        </collision>
        <inertial>
            <origin rpy="0 0 0" xyz="0 0 0" />
            <mass value="8.513716091228341" />
            <inertia ixx="0.02837905363742781" ixy="0" ixz="0" iyy="0.02837905363742781" iyz="0" izz="0.04256858045614171" />
        </inertial>
    </link>
    <link name="arm1_r_link">
        <visual>
            <origin rpy="0 0 0" xyz="0 0 0" />
            <geometry>
                <cylinder length="0.1" radius="0.1" />
            </geometry>
            <material name="aluminum" />
        </visual>
        <collision>
            <origin rpy="0 0 0" xyz="0 0 0" />
            <geometry>
                <cylinder length="0.1" radius="0.1" />
            </geometry>
        </collision>
        <inertial>
            <origin rpy="0 0 0" xyz="0 0 0" />
            <mass value="8.513716091228341" />
            <inertia ixx="0.02837905363742781" ixy="0" ixz="0" iyy="0.02837905363742781" iyz="0" izz="0.04256858045614171" />
        </inertial>
    </link>
    <link name="arm2_link">
        <visual>
            <origin rpy="0 0 0" xyz="0 0 0.2" />
            <geometry>
                <cylinder length="0.5" radius="0.1" />
            </geometry>
            <material name="aluminum" />
        </visual>
        <collision>
            <origin rpy="0 0 0" xyz="0 0 0.2" />
            <geometry>
                <cylinder length="0.5" radius="0.1" />
            </geometry>
        </collision>
        <inertial>
            <origin rpy="0 0 0" xyz="0 0 0.2" />
            <mass value="42.5685804561417" />
            <inertia ixx="0.9932668773099732" ixy="0" ixz="0" iyy="0.9932668773099732" iyz="0" izz="0.21284290228070854" />
        </inertial>
    </link>
    <link name="arm3_link">
        <visual>
            <origin rpy="0 0 0" xyz="0 0 0.2" />
            <geometry>
                <cylinder length="0.5" radius="0.1" />
            </geometry>
            <material name="aluminum" />
        </visual>
        <collision>
            <origin rpy="0 0 0" xyz="0 0 0.2" />
            <geometry>
                <cylinder length="0.5" radius="0.1" />
            </geometry>
        </collision>
        <inertial>
            <origin rpy="0 0 0" xyz="0 0 0.2" />
            <mass value="42.5685804561417" />
            <inertia ixx="0.9932668773099732" ixy="0" ixz="0" iyy="0.9932668773099732" iyz="0" izz="0.21284290228070854" />
        </inertial>
    </link>
    <link name="arm4_link">
        <visual>
            <origin rpy="0 0 0" xyz="0 0 0.2" />
            <geometry>
                <cylinder length="0.5" radius="0.08" />
            </geometry>
            <material name="aluminum" />
        </visual>
        <collision>
            <origin rpy="0 0 0" xyz="0 0 0.2" />
            <geometry>
                <cylinder length="0.5" radius="0.08" />
            </geometry>
        </collision>
        <inertial>
            <origin rpy="0 0 0" xyz="0 0 0.2" />
            <mass value="27.24389149193069" />
            <inertia ixx="0.6111712991356452" ixy="0" ixz="0" iyy="0.6111712991356452" iyz="0" izz="0.0871804527741782" />
        </inertial>
    </link>
    <link name="arm5_link">
        <visual>
            <origin rpy="0 0 0" xyz="0 0 0" />
            <geometry>
                <cylinder length="0.02" radius="0.1" />
            </geometry>
            <material name="aluminum" />
        </visual>
        <collision>
            <origin rpy="0 0 0" xyz="0 0 0" />
            <geometry>
                <cylinder length="0.02" radius="0.1" />
            </geometry>
        </collision>
        <inertial>
            <origin rpy="0 0 0" xyz="0 0 0" />
            <mass value="1.702743218245668" />
            <inertia ixx="0.004313616152889027" ixy="0" ixz="0" iyy="0.004313616152889027" iyz="0" izz="0.00851371609122834" />
        </inertial>
    </link>
    <link name="arm6_link">
        <visual>
            <origin rpy="0 0 0" xyz="0 0 0" />
            <geometry>
                <box size="0.02 0.2 0.02" />
            </geometry>
            <material name="aluminum" />
        </visual>
        <collision>
            <origin rpy="0 0 0" xyz="0 0 0" />
            <geometry>
                <box size="0.02 0.2 0.02" />
            </geometry>
        </collision>
        <inertial>
            <origin rpy="0 0 0" xxyz="0 0 0" xyz="0 0 0" />
            <mass value="0.21680000000000005" />
            <inertia ixx="0.0007298933333333336" ixy="0" ixz="0" iyy="1.4453333333333338e-05" iyz="0" izz="0.0007298933333333336" />
        </inertial>
    </link>
    <!-- Arm Joints -->
    <joint name="arm1_p_joint" type="prismatic">
        <parent link="base_link" />
        <child link="arm1_p_link" />
        <origin rpy="0 0 0" xyz="0 0 0.1" />
        <axis xyz="0 1 0" />
        <limit effort="100" lower="-0.4" upper="0.4" velocity="0.1" />
    </joint>
    <joint name="arm1_r_joint" type="revolute">
        <parent link="arm1_p_link" />
        <child link="arm1_r_link" />
        <origin rpy="0 0 0" xyz="0 0 0.1" />
        <axis xyz="0 0 1" />
        <limit effort="100" lower="-1.57" upper="1.57" velocity="0.1" />
    </joint>
    <joint name="arm2_joint" type="revolute">
        <parent link="arm1_r_link" />
        <child link="arm2_link" />
        <origin rpy="0 0 0" xyz="0 -0.2 -0" />
        <axis xyz="0 1 0" />
        <limit effort="100" lower="-1.68" upper="2.01" velocity="0.1" />
    </joint>
    <joint name="arm3_joint" type="revolute">
        <parent link="arm2_link" />
        <child link="arm3_link" />
        <origin rpy="0 0 0" xyz="0 0.2 0.4" />
        <axis xyz="0 1 0" />
        <limit effort="100" lower="-2.80" upper="2.80" velocity="0.1" />
    </joint>
    <joint name="arm4_joint" type="prismatic">
        <parent link="arm3_link" />
        <child link="arm4_link" />
        <origin rpy="0 0 0" xyz="0 0 0" />
        <axis xyz="0 0 1" />
        <limit effort="100" lower="0" upper="0.5" velocity="0.1" />
    </joint>
    <joint name="arm5_joint" type="revolute">
        <parent link="arm4_link" />
        <child link="arm5_link" />
        <origin rpy="0 0 0" xyz="0 0 0.45" />
        <axis xyz="0 0 1" />
        <limit effort="100" lower="-2.80" upper="2.80" velocity="0.1" />
    </joint>
    <joint name="arm6_joint" type="fixed">
        <parent link="arm5_link" />
        <child link="arm6_link" />
        <origin rpy="0 0 0" xyz="0 0 0.02" />
    </joint>
    <!-- Gripper Components -->
    <link name="gripper_left">
        <visual>
            <origin rpy="0 0 0" xyz="0 0 0" />
            <geometry>
                <box size="0.02 0.02 0.1" />
            </geometry>
            <material name="aluminum" />
        </visual>
        <collision>
            <origin rpy="0 0 0" xyz="0 0 0" />
            <geometry>
                <box size="0.02 0.02 0.1" />
            </geometry>
        </collision>
        <inertial>
            <origin rpy="0 0 0" xxyz="0 0 0" xyz="0 0 0" />
            <mass value="0.10840000000000001" />
            <inertia ixx="9.39466666666667e-05" ixy="0" ixz="0" iyy="9.39466666666667e-05" iyz="0" izz="7.226666666666668e-06" />
        </inertial>
    </link>
    <link name="gripper_right">
        <visual>
            <origin rpy="0 0 0" xyz="0 0 0" />
            <geometry>
                <box size="0.02 0.02 0.1" />
            </geometry>
            <material name="aluminum" />
        </visual>
        <collision>
            <origin rpy="0 0 0" xyz="0 0 0" />
            <geometry>
                <box size="0.02 0.02 0.1" />
            </geometry>
        </collision>
        <inertial>
            <origin rpy="0 0 0" xxyz="0 0 0" xyz="0 0 0" />
            <mass value="0.10840000000000001" />
            <inertia ixx="9.39466666666667e-05" ixy="0" ixz="0" iyy="9.39466666666667e-05" iyz="0" izz="7.226666666666668e-06" />
        </inertial>
    </link>
    <joint name="gripper_joint1" type="prismatic">
        <parent link="arm6_link" />
        <child link="gripper_left" />
        <origin rpy="0 0 0" xyz="0 0.09 0.05" />
        <axis xyz="0 1 0" />
        <limit effort="100" lower="-0.08" upper="0" velocity="0.1" />
    </joint>
    <joint name="gripper_joint2" type="prismatic">
        <parent link="arm6_link" />
        <child link="gripper_right" />
        <origin rpy="0 0 0" xyz="0 -0.09 0.05" />
        <axis xyz="0 1 0" />
        <limit effort="100" lower="0" upper="0.08" velocity="0.1" />
    </joint>
    <transmission name="trans_arm1_p_joint">
        <type>transmission_interface/SimpleTransmission</type>
        <joint name="arm1_p_joint">
            <hardwareInterface>hardware_interface/EffortJointInterface</hardwareInterface>
        </joint>
        <actuator name="motor_arm1_p_joint">
            <mechanicalReduction>1</mechanicalReduction>
            <hardwareInterface>hardware_interface/EffortJointInterface</hardwareInterface>
        </actuator>
    </transmission>
    <transmission name="trans_arm1_r_joint">
        <type>transmission_interface/SimpleTransmission</type>
        <joint name="arm1_r_joint">
            <hardwareInterface>hardware_interface/EffortJointInterface</hardwareInterface>
        </joint>
        <actuator name="motor_arm1_r_joint">
            <mechanicalReduction>1</mechanicalReduction>
            <hardwareInterface>hardware_interface/EffortJointInterface</hardwareInterface>
        </actuator>
    </transmission>
    <transmission name="trans_arm2_joint">
        <type>transmission_interface/SimpleTransmission</type>
        <joint name="arm2_joint">
            <hardwareInterface>hardware_interface/EffortJointInterface</hardwareInterface>
        </joint>
        <actuator name="motor_arm2_joint">
            <mechanicalReduction>1</mechanicalReduction>
            <hardwareInterface>hardware_interface/EffortJointInterface</hardwareInterface>
        </actuator>
    </transmission>
    <transmission name="trans_arm3_joint">
        <type>transmission_interface/SimpleTransmission</type>
        <joint name="arm3_joint">
            <hardwareInterface>hardware_interface/EffortJointInterface</hardwareInterface>
        </joint>
        <actuator name="motor_arm3_joint">
            <mechanicalReduction>1</mechanicalReduction>
            <hardwareInterface>hardware_interface/EffortJointInterface</hardwareInterface>
        </actuator>
    </transmission>
    <transmission name="trans_arm4_joint">
        <type>transmission_interface/SimpleTransmission</type>
        <joint name="arm4_joint">
            <hardwareInterface>hardware_interface/EffortJointInterface</hardwareInterface>
        </joint>
        <actuator name="motor_arm4_joint">
            <mechanicalReduction>1</mechanicalReduction>
            <hardwareInterface>hardware_interface/EffortJointInterface</hardwareInterface>
        </actuator>
    </transmission>
    <transmission name="trans_arm5_joint">
        <type>transmission_interface/SimpleTransmission</type>
        <joint name="arm5_joint">
            <hardwareInterface>hardware_interface/EffortJointInterface</hardwareInterface>
        </joint>
        <actuator name="motor_arm5_joint">
            <mechanicalReduction>1</mechanicalReduction>
            <hardwareInterface>hardware_interface/EffortJointInterface</hardwareInterface>
        </actuator>
    </transmission>
    <transmission name="trans_gripper_joint1">
        <type>transmission_interface/SimpleTransmission</type>
        <joint name="gripper_joint1">
            <hardwareInterface>hardware_interface/EffortJointInterface</hardwareInterface>
        </joint>
        <actuator name="motor_gripper_joint1">
            <mechanicalReduction>1</mechanicalReduction>
            <hardwareInterface>hardware_interface/EffortJointInterface</hardwareInterface>
        </actuator>
    </transmission>
    <transmission name="trans_gripper_joint2">
        <type>transmission_interface/SimpleTransmission</type>
        <joint name="gripper_joint2">
            <hardwareInterface>hardware_interface/EffortJointInterface</hardwareInterface>
        </joint>
        <actuator name="motor_gripper_joint2">
            <mechanicalReduction>1</mechanicalReduction>
            <hardwareInterface>hardware_interface/EffortJointInterface</hardwareInterface>
        </actuator>
    </transmission>
    <!-- Mount the arm onto the base with a fixed joint.
       Adjust the xyz values so that the arm is mounted at the proper height.
       In this example, we attach the arm’s base_link to the body_link. -->
    <joint name="arm_mount_joint" type="fixed">
        <parent link="body_link" />
        <child link="base_link" />
        <origin rpy="0 0 0" xyz="0 0 0.4" />
    </joint>
    <transmission name="trans_wheel1_joint">
        <type>transmission_interface/SimpleTransmission</type>
        <joint name="wheel1_joint">
            <hardwareInterface>hardware_interface/EffortJointInterface</hardwareInterface>
        </joint>
        <actuator name="wheel1_joint_motor">
            <hardwareInterface>hardware_interface/EffortJointInterface</hardwareInterface>
            <mechanicalReduction>1</mechanicalReduction>
        </actuator>
    </transmission>
    <transmission name="trans_wheel2_joint">
        <type>transmission_interface/SimpleTransmission</type>
        <joint name="wheel2_joint">
            <hardwareInterface>hardware_interface/EffortJointInterface</hardwareInterface>
        </joint>
        <actuator name="wheel2_joint_motor">
            <hardwareInterface>hardware_interface/EffortJointInterface</hardwareInterface>
            <mechanicalReduction>1</mechanicalReduction>
        </actuator>
    </transmission>
    <transmission name="trans_wheel3_joint">
        <type>transmission_interface/SimpleTransmission</type>
        <joint name="wheel3_joint">
            <hardwareInterface>hardware_interface/EffortJointInterface</hardwareInterface>
        </joint>
        <actuator name="wheel3_joint_motor">
            <hardwareInterface>hardware_interface/EffortJointInterface</hardwareInterface>
            <mechanicalReduction>1</mechanicalReduction>
        </actuator>
    </transmission>
    <transmission name="trans_wheel4_joint">
        <type>transmission_interface/SimpleTransmission</type>
        <joint name="wheel4_joint">
            <hardwareInterface>hardware_interface/EffortJointInterface</hardwareInterface>
        </joint>
        <actuator name="wheel4_joint_motor">
            <hardwareInterface>hardware_interface/EffortJointInterface</hardwareInterface>
            <mechanicalReduction>1</mechanicalReduction>
        </actuator>
    </transmission>
</robot>

